<?xml version="1.0"?>

  <robot name="New_Robot">
    <link name="base_link">
      <visual>
        <geometry> <box size="0.4 0.6 0.2 " />  </geometry>
        <material name="green"><color rgba="0 1 0 1" />  </material>
      </visual>
    </link>

    <link name="first_link">
      <inertial>
        <origin xyz="0 0 0" rpy="0 0 0" />
        <mass value="1" />
        <inertia ixx="1" ixy="0" ixz="0" iyy="0.083" iyz="0" izz="1" />
      </inertial>
      <visual>
           <origin xyz="0 0 .5"/>
           <geometry> <cylinder length="1" radius="0.05" /> </geometry>
           <material name="red">  <color rgba="1 0 0 1" /></material>
      </visual>
    </link>
    <joint name="joint_one" type="revolute">
      <parent link="base_link" />
      <child link="first_link" />
      <origin xyz="0 0 0.1" rpy = "0 0 0"/>
      <axis xyz="0 1 0" />
      <dynamics damping="0.1" />
    </joint>
    <link name="second_link">
      <inertial>
        <origin xyz="0.5 0 0" rpy="0 0 0" />
        <mass value="1" />
        <inertia ixx="1" ixy="0" ixz="0" iyy="0.33" iyz="0" izz="1" />
      </inertial>
      <visual>
        <origin xyz="0 0 0.5 "/>
        <geometry> <cylinder length="1" radius="0.05" /> </geometry>
        <material name="blue"> <color rgba="0 0 1 1" /> </material>
      </visual>
    </link>

    <joint name="joint_two" type="revolute">
      <parent link="first_link" />
      <child link="second_link" />
      <origin xyz="0 0 1" rpy="0.0 0 0 "/>
      <axis xyz="1 0 0" />
      <dynamics damping="0.1" />
    </joint>

    <link name="third_link">
      <inertial>
        <origin xyz="0.5 0 0" rpy="0 0 0" />
        <mass value="1" />
        <inertia ixx="1" ixy="0" ixz="0" iyy="0.33" iyz="0" izz="1" />
      </inertial>
      <visual>
        <origin xyz="0 0 0.5 "/>
        <geometry> <cylinder length="1" radius="0.05" /> </geometry>
        <material name="yellow"> <color rgba="1 1 0 1" /> </material>
      </visual>
    </link>

    <joint name="joint_three" type="revolute">
      <parent link="second_link" />
      <child link="third_link" />
      <origin xyz="0 0 1" rpy="0.0 0 0 "/>
      <axis xyz="0 1 0" />
      <dynamics damping="0.1" />
    </joint>

    <link name="fourth_link">
      <inertial>
        <origin xyz="0 0 0" rpy="0 0 0" />
        <mass value="1" />
        <inertia ixx="0" ixy="0" ixz="0" iyy="1" iyz="0" izz="1" />
      </inertial>
      <visual>
           <origin xyz="0 0.5 0"/>
           <geometry> <box size="0.05 1.0  0.05" /></geometry>
           <material name="red">  <color rgba="1 0 0 1" /></material>
      </visual>
          </link>
    <joint name="joint-four" type="continuous">
      <parent link="third_link" />
      <child link="fourth_link" />
      <origin xyz="0 0 1" rpy="0.0 0 0 "/>
      <axis xyz="0 1 0" />
      <dynamics damping="0.1" />
    </joint>

    <link name="fifth_link">
      <inertial>
        <origin xyz="0 0 0" rpy="0 0 0" />
        <mass value="1" />
        <inertia ixx="0" ixy="0" ixz="0" iyy="1" iyz="0" izz="1" />
      </inertial>
      <visual>
           <origin xyz="0.5 0 0"/>
           <geometry> <box size="1 0.05  0.05" /></geometry>
           <material name="green">  <color rgba="0 1 0 1" /></material>
      </visual>
          </link>
    <joint name="joint_five" type="continuous">
      <parent link="fourth_link" />
      <child link="fifth_link" />
      <origin xyz="0 1 0" rpy="0.0 0 0 "/>
      <axis xyz="1 0 0" />
      <dynamics damping="0.1" />
    </joint>

    <link name="branch_link">
      <inertial>
        <origin xyz="0 0 0" rpy="0 0 0" />
        <mass value="1" />
        <inertia ixx="0" ixy="0" ixz="0" iyy="1" iyz="0" izz="1" />
      </inertial>
      <visual>
           <origin xyz="-0.025 0 0"/>
           <geometry> <box size="0.05 1 1" /></geometry>
           <material name="green">  <color rgba="0 1 0 1" /></material>
      </visual>
      <collision>
        <geometry> <box size="0.05 1 1" /></geometry>
        <origin xyz="-0.025 0 0"/>
      </collision>
    </link>

      <joint name="joint_six" type="revolute">
        <parent link="fifth_link" />
        <child link="branch_link" />
        <origin xyz="1.05 0 0" rpy="0.0 0 0 "/>
        <axis xyz="1 0 0" />
        <dynamics damping="0.1" />
      </joint>

      <link name="first_finger">
        <inertial>
          <origin xyz="0 0 0" rpy="0 0 0" />
          <mass value="1" />
          <inertia ixx="0" ixy="0" ixz="0" iyy="1" iyz="0" izz="1" />
        </inertial>
        <visual>
             <origin xyz="0.125 0 0"/>
             <geometry> <box size="0.25 .05 .05" /></geometry>
             <material name="green">  <color rgba="0 1 0 1" /></material>
        </visual>
        <collision>
             <geometry> <box size="0.25 .05 .05" /></geometry>
          <origin xyz="0.125 0 0"/>
        </collision>
      </link>
      <link name="second_finger">
        <inertial>
          <origin xyz="0 0 0" rpy="0 0 0" />
          <mass value="1" />
          <inertia ixx="0" ixy="0" ixz="0" iyy="1" iyz="0" izz="1" />
        </inertial>
        <visual>
             <origin xyz="0.125 0 0"/>
             <geometry> <box size="0.25 .05 .05" /></geometry>
             <material name="green">  <color rgba="0 1 0 1" /></material>
        </visual>
        <collision>
             <geometry> <box size="0.25 .05 .05" /></geometry>
          <origin xyz="0.125 0 0"/>
        </collision>
      </link>

        <joint name="first_finger_joint " type="revolute">
          <parent link="branch_link" />
          <child link="first_finger" />
          <origin xyz="0 -0.25 0.25" rpy="0.0 0 0 "/>
          <axis xyz="0 1 0" />
          <dynamics damping="0.1" />
        </joint>



          <joint name="second_finger_joint " type="revolute">
            <parent link="branch_link" />
            <child link="second_finger" />
            <origin xyz="0 -0.25 -0.25" rpy="0.0 0 0 "/>
            <axis xyz="0 1 0" />
            <dynamics damping="0.1" />
          </joint>

          <link name="third_finger">
            <inertial>
              <origin xyz="0 0 0" rpy="0 0 0" />
              <mass value="1" />
              <inertia ixx="0" ixy="0" ixz="0" iyy="1" iyz="0" izz="1" />
            </inertial>
            <visual>
                 <origin xyz="0.125 0 0"/>
                 <geometry> <box size="0.25 .05 .05" /></geometry>
                 <material name="green">  <color rgba="0 1 0 1" /></material>
            </visual>
            <collision>
                 <geometry> <box size="0.25 .05 .05" /></geometry>
              <origin xyz="0.125 0 0"/>
            </collision>
          </link>
          <link name="forth_finger">
            <inertial>
              <origin xyz="0 0 0" rpy="0 0 0" />
              <mass value="1" />
              <inertia ixx="0" ixy="0" ixz="0" iyy="1" iyz="0" izz="1" />
            </inertial>
            <visual>
                 <origin xyz="0.125 0 0"/>
                 <geometry> <box size="0.25 .05 .05" /></geometry>
                 <material name="green">  <color rgba="0 1 0 1" /></material>
            </visual>
            <collision>
                 <geometry> <box size="0.25 .05 .05" /></geometry>
              <origin xyz="0.125 0 0"/>
            </collision>
          </link>

          <joint name="third_finger_joint " type="revolute">
            <parent link="branch_link" />
            <child link="third_finger" />
            <origin xyz="0 +0.25 -0.25" rpy="0.0 0 0 "/>
            <axis xyz="0 1 0" />
            <dynamics damping="0.1" />
          </joint>



            <joint name="forth_finger_joint " type="revolute">
              <parent link="branch_link" />
              <child link="forth_finger" />
              <origin xyz="0 +0.25 +0.25" rpy="0.0 0 0 "/>
              <axis xyz="0 1 0" />
              <dynamics damping="0.1" />
            </joint>


</robot>
